Workbook

Sheet Raw_Data
A1: Ticket_ID | B1: Day | C1: Department | D1: Issue_Type | E1: Priority | F1: Response_Minutes | G1: Resolution_Hours | H1: Resolved_First_Contact | I1: Technician | J1: Satisfaction
A2: TK4000 | B2: 1 | C2: HR | D2: Software | E2: Low | F2: 77 | G2: 8.9 | H2: No | I2: Dina | J2: 3.8
A3: TK4001 | B3: 2 | C3: Registrar | D3: Network | E3: Low | F3: 79 | G3: 4.4 | H3: Yes | I3: Ana | J3: 3.3
A4: TK4002 | B4: 3 | C4: Library | D4: Password | E4: Low | F4: 7 | G4: 10.8 | H4: Yes | I4: Ben | J4: 3.8
A5: TK4003 | B5: 4 | C5: Registrar | D5: Network | E5: High | F5: 19 | G5: 8.7 | H5: Yes | I5: Ben | J5: 3.9
A6: TK4004 | B6: 5 | C6: IT | D6: Software | E6: High | F6: 32 | G6: 5.7 | H6: No | I6: Ben | J6: 4.2
A7: TK4005 | B7: 6 | C7: Finance | D7: Password | E7: Medium | F7: 77 | G7: 10.5 | H7: Yes | I7: Ben | J7: 2.6 | L7: Response time | M7: values
A8: TK4006 | B8: 7 | C8: Finance | D8: Password | E8: Medium | F8: 6 | G8: 8.7 | H8: Yes | I8: Dina | J8: 4.2 | L8: mean | M8: =AVERAGE(Raw_Data!F2:F51) -> 55.5
A9: TK4007 | B9: 8 | C9: HR | D9: Account | E9: Medium | F9: 112 | G9: 4.4 | H9: Yes | I9: Dina | J9: 3.5 | L9: median | M9: =MEDIAN(F2:F51) -> 46
A10: TK4008 | B10: 9 | C10: Library | D10: Software | E10: Medium | F10: 43 | G10: 9.3 | H10: No | I10: Ben | J10: 3.7 | L10: minimum | M10: =MIN(F2:F51) -> 6
A11: TK4009 | B11: 10 | C11: IT | D11: Network | E11: Medium | F11: 51 | G11: 7.5 | H11: No | I11: Ben | J11: 4 | L11: maximum | M11: =MAX(F2:F51) -> 118
A12: TK4010 | B12: 11 | C12: HR | D12: Software | E12: Low | F12: 35 | G12: 11.3 | H12: No | I12: Ben | J12: 3.8
A13: TK4011 | B13: 12 | C13: HR | D13: Hardware | E13: Medium | F13: 115 | G13: 3.1 | H13: No | I13: Carlo | J13: 3.8 | L13: Resolution Time | M13: Values
A14: TK4012 | B14: 13 | C14: Registrar | D14: Network | E14: Critical | F14: 82 | G14: 3 | H14: Yes | I14: Carlo | J14: 4.4 | L14: mean | M14: =AVERAGE(G2:G51) -> 6.532
A15: TK4013 | B15: 14 | C15: HR | D15: Network | E15: Medium | F15: 42 | G15: 4 | H15: Yes | I15: Dina | J15: 4.2 | L15: median | M15: =MEDIAN(G2:G51) -> 6.15
A16: TK4014 | B16: 15 | C16: Library | D16: Password | E16: Critical | F16: 58 | G16: 6.3 | H16: Yes | I16: Carlo | J16: 3.3 | L16: minimum | M16: =MIN(G2:G51) -> 0.8
A17: TK4015 | B17: 16 | C17: Library | D17: Hardware | E17: Medium | F17: 96 | G17: 11 | H17: No | I17: Carlo | J17: 3.3 | L17: maximum | M17: =MAX(G2:G51) -> 11.6
A18: TK4016 | B18: 17 | C18: HR | D18: Account | E18: Low | F18: 48 | G18: 5.7 | H18: Yes | I18: Dina | J18: 3.8
A19: TK4017 | B19: 18 | C19: IT | D19: Network | E19: Critical | F19: 36 | G19: 2.4 | H19: No | I19: Dina | J19: 5
A20: TK4018 | B20: 19 | C20: IT | D20: Hardware | E20: Medium | F20: 77 | G20: 4.5 | H20: Yes | I20: Dina | J20: 3.2
A21: TK4019 | B21: 20 | C21: Registrar | D21: Account | E21: Medium | F21: 118 | G21: 11.1 | H21: Yes | I21: Dina | J21: 3.9 | L21: mean | M21: =AVERAGE(F2:F51) -> 55.5
A22: TK4020 | B22: 21 | C22: Registrar | D22: Hardware | E22: High | F22: 28 | G22: 5.5 | H22: No | I22: Carlo | J22: 3.9 | L22: =MEDIAN(F2:F51) -> 46
A23: TK4021 | B23: 22 | C23: Library | D23: Password | E23: Low | F23: 100 | G23: 11.5 | H23: Yes | I23: Dina | J23: 2.9 | L23: =MIN(F2:F51) -> 6
A24: TK4022 | B24: 23 | C24: Library | D24: Password | E24: High | F24: 74 | G24: 7.8 | H24: Yes | I24: Ben | J24: 4.2 | L24: =MAX(G2:G51) -> 11.6
A25: TK4023 | B25: 24 | C25: Registrar | D25: Network | E25: Low | F25: 114 | G25: 1.6 | H25: Yes | I25: Ben | J25: 3.8
A26: TK4024 | B26: 25 | C26: HR | D26: Hardware | E26: High | F26: 14 | G26: 2.9 | H26: Yes | I26: Ben | J26: 5 | L26: =SUM(G2:G51) -> 326.6
A27: TK4025 | B27: 26 | C27: IT | D27: Hardware | E27: Medium | F27: 40 | G27: 6.4 | H27: Yes | I27: Dina | J27: 3.6
A28: TK4026 | B28: 27 | C28: IT | D28: Network | E28: Low | F28: 6 | G28: 6 | H28: Yes | I28: Ana | J28: 3.9
A29: TK4027 | B29: 28 | C29: IT | D29: Hardware | E29: Medium | F29: 88 | G29: 9.1 | H29: No | I29: Dina | J29: 3
A30: TK4028 | B30: 29 | C30: HR | D30: Network | E30: High | F30: 87 | G30: 11.6 | H30: No | I30: Dina | J30: 2.5
A31: TK4029 | B31: 30 | C31: IT | D31: Password | E31: High | F31: 13 | G31: 10.1 | H31: No | I31: Ben | J31: 3.4
A32: TK4030 | B32: 31 | C32: Finance | D32: Account | E32: High | F32: 32 | G32: 10.3 | H32: Yes | I32: Carlo | J32: 3.2
A33: TK4031 | B33: 32 | C33: Finance | D33: Password | E33: Low | F33: 29 | G33: 8 | H33: No | I33: Ana | J33: 5
A34: TK4032 | B34: 33 | C34: IT | D34: Hardware | E34: Medium | F34: 10 | G34: 1.8 | H34: No | I34: Ben | J34: 4.5
A35: TK4033 | B35: 34 | C35: Registrar | D35: Account | E35: Medium | F35: 116 | G35: 5.6 | H35: Yes | I35: Ben | J35: 3.2
A36: TK4034 | B36: 35 | C36: Library | D36: Password | E36: High | F36: 16 | G36: 6.2 | H36: Yes | I36: Carlo | J36: 4.8
A37: TK4035 | B37: 36 | C37: Finance | D37: Account | E37: High | F37: 28 | G37: 8.7 | H37: Yes | I37: Carlo | J37: 3.1
A38: TK4036 | B38: 37 | C38: IT | D38: Software | E38: Medium | F38: 106 | G38: 2.7 | H38: No | I38: Ben | J38: 3.3
... A51: TK4049 | B51: 50 | C51: HR | D51: Password | E51: Medium | F51: 42 | G51: 0.8 | H51: Yes | I51: Carlo | J51: 5

Sheet Data_Dictionary
A1: DATA DICTIONARY — IT Help Desk Ticket Data (Raw_Data)
A3: Variable | B3: Description | C3: Data Type | D3: Valid Values / Range | E3: Example
A4: Ticket_ID | B4: Unique identifier for each help desk ticket | C4: Text | D4: TK4000–TK4049 | E4: TK4000
A5: Day | B5: Sequential day number the ticket was logged on | C5: Integer | D5: 1–50 | E5: 1
A6: Department | B6: Department that submitted the ticket | C6: Text (categorical) | D6: Finance, HR, IT, Library, Registrar | E6: HR
A7: Issue_Type | B7: Category of the reported IT issue | C7: Text (categorical) | D7: Account, Hardware, Network, Password, Software | E7: Software
A8: Priority | B8: Urgency level assigned to the ticket | C8: Text (categorical) | D8: Low, Medium, High, Critical | E8: Low
A9: Response_Minutes | B9: Time elapsed between ticket submission and first technician response, in minutes | C9: Integer | D9: 6–118 | E9: 77
A10: Resolution_Hours | B10: Total time to resolve the ticket, in hours | C10: Decimal | D10: 0.8–11.6 | E10: 8.9
A11: Resolved_First_Contact | B11: Whether the ticket was resolved during the first technician interaction | C11: Text (Yes/No) | D11: Yes, No | E11: No
A12: Technician | B12: Technician assigned to handle the ticket | C12: Text (categorical) | D12: Ana, Ben, Carlo, Dina | E12: Dina
A13: Satisfaction | B13: Customer satisfaction rating for the ticket | C13: Decimal | D13: 2.5–5.0 (scale of 1–5) | E13: 3.8

Sheet Tasks
A1: ANALYSIS TASKS / REQUIREMENTS
A2: Reconstructed from the completed analysis (Sheet1/Analysis) — replace with the original task wording if different.
A4: # | B4: Task
A5: 1 | B5: Check the dataset for missing values and possible invalid entries.
A6: 2 | B6: Check for duplicate tickets or other data errors.
A7: 3 | B7: Calculate descriptive statistics (mean, median, minimum, maximum) for response time and resolution time.
A8: 4 | B8: Determine the total number of help desk tickets recorded.
A9: 5 | B9: Determine the number and percentage of tickets by issue type.
A10: 6 | B10: Determine the number and percentage of tickets by priority level.
A11: 7 | B11: Calculate the average response time by priority level.
A12: 8 | B12: Calculate the average resolution time by issue type.
A13: 9 | B13: Calculate the percentage of tickets resolved on first contact.
A14: 10 | B14: Calculate average customer satisfaction rating by issue type and by priority level.
A15: 11 | B15: Compare technician performance (ticket volume, average resolution time, average satisfaction).
A16: 12 | B16: Create charts to visualize tickets by issue type, tickets by priority, and average resolution time by issue type.
... A19: 15 | B19: Provide recommendations based on the findings.

Sheet Tasks(Answer)
A1: question | B1: Answer
A2: question 1. | B2: no missing value and possible invalid values
A3: question 2. | B3: No possible duplicate tickets and data errors
A4: question 3. | B4: Response Time: mean 55.5 min, median 46.0 min, min 6 min, max 118 min. Resolution Time: mean 6.53 hrs, median 6.15 hrs, min 0.8 hrs, max 11.6 hrs. See Analysis sheet, Q3 table.
A5: question 4. | B5: 50 total help desk tickets recorded. See Analysis sheet, Q4.
A6: question 5. | B6: Password 12, Network 11, Hardware 11, Account 9, Software 7 tickets. Password issues are the most common (24% of all tickets). See Analysis sheet, Q5 table and Charts sheet (Tickets by Issue Type).
A7: question 6. | B7: Medium 21, High 14, Low 11, Critical 4 tickets. Most tickets (42%) are Medium priority. See Analysis sheet, Q6 table and Charts sheet (Tickets by Priority).
A8: question 7. | B8: Avg response time by priority: Critical 62.3 min, High 32.4 min, Low 57.0 min, Medium 68.9 min. High-priority tickets get the fastest response, but Critical tickets are answered slower than both High and Low priority tickets — a notable SLA misalignment. See Analysis sheet, Q7 table.
A9: question 8. | B9: Avg resolution time by issue type: Password 7.7 hrs, Software 7.0 hrs, Account 6.6 hrs, Hardware 5.9 hrs, Network 5.5 hrs. Password issues take the longest to resolve despite usually being simple fixes. See Analysis sheet, Q8 table and Charts sheet (Average Resolution Time by Issue Type).
A10: question 9. | B10: 29 of 50 tickets (58.0%) were resolved on first contact. See Analysis sheet, Q9.
A11: question 10. | B11: By issue type, avg satisfaction ranges narrowly from 3.68 (Hardware) to 3.92 (Network). By priority, satisfaction rises with priority: Critical 4.18, High 3.94, Low 3.70, Medium 3.68 — tickets escalated as urgent tend to leave users more satisfied once handled. See Analysis sheet, Q10 tables.
A12: question 11. | B12: Ana: 7 tickets, 6.0 hrs avg resolution, 4.17 avg satisfaction (best satisfaction, lowest load). Ben: 17 tickets, 6.9 hrs avg resolution, 3.78 avg satisfaction (highest ticket load). Carlo: 12 tickets, 5.7 hrs avg resolution, 3.91 avg satisfaction (fastest average resolution). Dina: 14 tickets, 7.0 hrs avg resolution, 3.53 avg satisfaction (slowest resolution, lowest satisfaction). See Analysis sheet, Q11 table.
... A16: question 15. | B16: Recommendations: (1) Fix the SLA/triage process so Critical tickets are routed and answered fastest — currently they wait longer on average than High-priority tickets. (2) Create a self-service password reset tool or improved documentation, since Password issues are both the most common and slowest-resolved category. (3) Rebalance ticket assignment across technicians (e.g., shift some of Ben's and Dina's load to Ana and Carlo) and review first-contact resolution training, since only 58% of tickets are closed on the first interaction.

Sheet Analysis
A1: IT HELP DESK TICKET ANALYSIS — Computations
A3: Q3. Descriptive Statistics — Response Time (min) & Resolution Time (hrs)
A4: Metric | B4: Response_Minutes | C4: Resolution_Hours
A5: Mean | B5: =AVERAGE(Raw_Data!$F$2:$F$51) -> 55.5 | C5: =AVERAGE(Raw_Data!$G$2:$G$51) -> 6.532
A6: Median | B6: =MEDIAN(Raw_Data!$F$2:$F$51) -> 46 | C6: =MEDIAN(Raw_Data!$G$2:$G$51) -> 6.15
A7: Minimum | B7: =MIN(Raw_Data!$F$2:$F$51) -> 6 | C7: =MIN(Raw_Data!$G$2:$G$51) -> 0.8
A8: Maximum | B8: =MAX(Raw_Data!$F$2:$F$51) -> 118 | C8: =MAX(Raw_Data!$G$2:$G$51) -> 11.6
A10: Q4. Total Number of Help Desk Tickets
A11: Total Tickets | B11: =COUNTA(Raw_Data!$A$2:$A$51) -> 50
A13: Q5. Number of Tickets by Issue Type
A14: Issue Type | B14: Number of Tickets | C14: % of Total
A15: Password | B15: =COUNTIF(Raw_Data!$D$2:$D$51,A15) -> 12 | C15: =B15/Analysis!$B$11 -> 0.24
A16: Network | B16: =COUNTIF(Raw_Data!$D$2:$D$51,A16) -> 11 | C16: =B16/Analysis!$B$11 -> 0.22
A17: Hardware | B17: =COUNTIF(Raw_Data!$D$2:$D$51,A17) -> 11 | C17: =B17/Analysis!$B$11 -> 0.22
A18: Software | B18: =COUNTIF(Raw_Data!$D$2:$D$51,A18) -> 7 | C18: =B18/Analysis!$B$11 -> 0.14
A19: Account | B19: =COUNTIF(Raw_Data!$D$2:$D$51,A19) -> 9 | C19: =B19/Analysis!$B$11 -> 0.18
A21: Q6. Number of Tickets by Priority Level
A22: Priority | B22: Number of Tickets | C22: % of Total
A23: Low | B23: =COUNTIF(Raw_Data!$E$2:$E$51,A23) -> 11 | C23: =B23/Analysis!$B$11 -> 0.22
A24: Medium | B24: =COUNTIF(Raw_Data!$E$2:$E$51,A24) -> 21 | C24: =B24/Analysis!$B$11 -> 0.42
A25: High | B25: =COUNTIF(Raw_Data!$E$2:$E$51,A25) -> 14 | C25: =B25/Analysis!$B$11 -> 0.28
A26: Critical | B26: =COUNTIF(Raw_Data!$E$2:$E$51,A26) -> 4 | C26: =B26/Analysis!$B$11 -> 0.08
A28: Q7. Average Response Time (min) by Priority Level
A29: Priority | B29: Avg Response Time (min)
A30: Low | B30: =AVERAGEIF(Raw_Data!$E$2:$E$51,A30,Raw_Data!$F$2:$F$51) -> 57
A31: Medium | B31: =AVERAGEIF(Raw_Data!$E$2:$E$51,A31,Raw_Data!$F$2:$F$51) -> 68.857143
A32: High | B32: =AVERAGEIF(Raw_Data!$E$2:$E$51,A32,Raw_Data!$F$2:$F$51) -> 32.357143
A33: Critical | B33: =AVERAGEIF(Raw_Data!$E$2:$E$51,A33,Raw_Data!$F$2:$F$51) -> 62.25
A35: Q8. Average Resolution Time (hrs) by Issue Type
A36: Issue Type | B36: Avg Resolution Time (hrs)
A37: Password | B37: =AVERAGEIF(Raw_Data!$D$2:$D$51,A37,Raw_Data!$G$2:$G$51) -> 7.7333333
A38: Network | B38: =AVERAGEIF(Raw_Data!$D$2:$D$51,A38,Raw_Data!$G$2:$G$51) -> 5.5363636
A39: Hardware | B39: =AVERAGEIF(Raw_Data!$D$2:$D$51,A39,Raw_Data!$G$2:$G$51) -> 5.8818182
A40: Software | B40: =AVERAGEIF(Raw_Data!$D$2:$D$51,A40,Raw_Data!$G$2:$G$51) -> 7.0285714
A41: Account | B41: =AVERAGEIF(Raw_Data!$D$2:$D$51,A41,Raw_Data!$G$2:$G$51) -> 6.5555556
A43: Q9. Percentage of Tickets Resolved on First Contact
A44: Resolved on First Contact (Yes count) | B44: =COUNTIF(Raw_Data!$H$2:$H$51,"Yes") -> 29
A45: % Resolved on First Contact | B45: =COUNTIF(Raw_Data!$H$2:$H$51,"Yes")/Analysis!$B$11 -> 0.58
A47: Q10. Average Customer Satisfaction Rating
A48: By Issue Type
...

Sheet PivotTable
A1: PIVOT SUMMARY — Issue Type x Priority
A2: Built with COUNTIFS / AVERAGEIFS so it recalculates like a live pivot; select the table and use Insert > PivotTable on Raw_Data for an interactive Excel PivotTable if required.
A4: Issue Type | B4: Priority | C4: Number of Tickets | D4: Avg Response Time (min) | E4: Avg Resolution Time (hrs)
A5: Password | B5: Low | C5: =COUNTIFS(Raw_Data!$D$2:$D$51,A5,Raw_Data!$E$2:$E$51,B5) -> 3 | D5: =IFERROR(AVERAGEIFS(Raw_Data!$F$2:$F$51,Raw_Data!$D$2:$D$51,A5,Raw_Data!$E$2:$E$51,B5),"") -> 45.333333 | E5: =IFERROR(AVERAGEIFS(Raw_Data!$G$2:$G$51,Raw_Data!$D$2:$D$51,A5,Raw_Data!$E$2:$E$51,B5),"") -> 10.1
A6: Password | B6: Medium | C6: =COUNTIFS(Raw_Data!$D$2:$D$51,A6,Raw_Data!$E$2:$E$51,B6) -> 5 | D6: =IFERROR(AVERAGEIFS(Raw_Data!$F$2:$F$51,Raw_Data!$D$2:$D$51,A6,Raw_Data!$E$2:$E$51,B6),"") -> 47.4 | E6: =IFERROR(AVERAGEIFS(Raw_Data!$G$2:$G$51,Raw_Data!$D$2:$D$51,A6,Raw_Data!$E$2:$E$51,B6),"") -> 6.42
A7: Password | B7: High | C7: =COUNTIFS(Raw_Data!$D$2:$D$51,A7,Raw_Data!$E$2:$E$51,B7) -> 3 | D7: =IFERROR(AVERAGEIFS(Raw_Data!$F$2:$F$51,Raw_Data!$D$2:$D$51,A7,Raw_Data!$E$2:$E$51,B7),"") -> 34.333333 | E7: =IFERROR(AVERAGEIFS(Raw_Data!$G$2:$G$51,Raw_Data!$D$2:$D$51,A7,Raw_Data!$E$2:$E$51,B7),"") -> 8.0333333
A8: Password | B8: Critical | C8: =COUNTIFS(Raw_Data!$D$2:$D$51,A8,Raw_Data!$E$2:$E$51,B8) -> 1 | D8: =IFERROR(AVERAGEIFS(Raw_Data!$F$2:$F$51,Raw_Data!$D$2:$D$51,A8,Raw_Data!$E$2:$E$51,B8),"") -> 58 | E8: =IFERROR(AVERAGEIFS(Raw_Data!$G$2:$G$51,Raw_Data!$D$2:$D$51,A8,Raw_Data!$E$2:$E$51,B8),"") -> 6.3
A9: Network | B9: Low | C9: =COUNTIFS(Raw_Data!$D$2:$D$51,A9,Raw_Data!$E$2:$E$51,B9) -> 3 | D9: =IFERROR(AVERAGEIFS(Raw_Data!$F$2:$F$51,Raw_Data!$D$2:$D$51,A9,Raw_Data!$E$2:$E$51,B9),"") -> 66.333333 | E9: =IFERROR(AVERAGEIFS(Raw_Data!$G$2:$G$51,Raw_Data!$D$2:$D$51,A9,Raw_Data!$E$2:$E$51,B9),"") -> 4
A10: Network | B10: Medium | C10: =COUNTIFS(Raw_Data!$D$2:$D$51,A10,Raw_Data!$E$2:$E$51,B10) -> 2 | D10: =IFERROR(AVERAGEIFS(Raw_Data!$F$2:$F$51,Raw_Data!$D$2:$D$51,A10,Raw_Data!$E$2:$E$51,B10),"") -> 46.5 | E10: =IFERROR(AVERAGEIFS(Raw_Data!$G$2:$G$51,Raw_Data!$D$2:$D$51,A10,Raw_Data!$E$2:$E$51,B10),"") -> 5.75
A11: Network | B11: High | C11: =COUNTIFS(Raw_Data!$D$2:$D$51,A11,Raw_Data!$E$2:$E$51,B11) -> 3 | D11: =IFERROR(AVERAGEIFS(Raw_Data!$F$2:$F$51,Raw_Data!$D$2:$D$51,A11,Raw_Data!$E$2:$E$51,B11),"") -> 39 | E11: =IFERROR(AVERAGEIFS(Raw_Data!$G$2:$G$51,Raw_Data!$D$2:$D$51,A11,Raw_Data!$E$2:$E$51,B11),"") -> 9.2
A12: Network | B12: Critical | C12: =COUNTIFS(Raw_Data!$D$2:$D$51,A12,Raw_Data!$E$2:$E$51,B12) -> 3 | D12: =IFERROR(AVERAGEIFS(Raw_Data!$F$2:$F$51,Raw_Data!$D$2:$D$51,A12,Raw_Data!$E$2:$E$51,B12),"") -> 63.666667 | E12: =IFERROR(AVERAGEIFS(Raw_Data!$G$2:$G$51,Raw_Data!$D$2:$D$51,A12,Raw_Data!$E$2:$E$51,B12),"") -> 3.2666667
A13: Hardware | B13: Low | C13: =COUNTIFS(Raw_Data!$D$2:$D$51,A13,Raw_Data!$E$2:$E$51,B13) -> 1 | D13: =IFERROR(AVERAGEIFS(Raw_Data!$F$2:$F$51,Raw_Data!$D$2:$D$51,A13,Raw_Data!$E$2:$E$51,B13),"") -> 83 | E13: =IFERROR(AVERAGEIFS(Raw_Data!$G$2:$G$51,Raw_Data!$D$2:$D$51,A13,Raw_Data!$E$2:$E$51,B13),"") -> 6.1
A14: Hardware | B14: Medium | C14: =COUNTIFS(Raw_Data!$D$2:$D$51,A14,Raw_Data!$E$2:$E$51,B14) -> 8 | D14: =IFERROR(AVERAGEIFS(Raw_Data!$F$2:$F$51,Raw_Data!$D$2:$D$51,A14,Raw_Data!$E$2:$E$51,B14),"") -> 72.125 | E14: =IFERROR(AVERAGEIFS(Raw_Data!$G$2:$G$51,Raw_Data!$D$2:$D$51,A14,Raw_Data!$E$2:$E$51,B14),"") -> 6.275
A15: Hardware | B15: High | C15: =COUNTIFS(Raw_Data!$D$2:$D$51,A15,Raw_Data!$E$2:$E$51,B15) -> 2 | D15: =IFERROR(AVERAGEIFS(Raw_Data!$F$2:$F$51,Raw_Data!$D$2:$D$51,A15,Raw_Data!$E$2:$E$51,B15),"") -> 21 | E15: =IFERROR(AVERAGEIFS(Raw_Data!$G$2:$G$51,Raw_Data!$D$2:$D$51,A15,Raw_Data!$E$2:$E$51,B15),"") -> 4.2
A16: Hardware | B16: Critical | C16: =COUNTIFS(Raw_Data!$D$2:$D$51,A16,Raw_Data!$E$2:$E$51,B16) -> 0 | D16: =IFERROR(AVERAGEIFS(Raw_Data!$F$2:$F$51,Raw_Data!$D$2:$D$51,A16,Raw_Data!$E$2:$E$51,B16),"") | E16: =IFERROR(AVERAGEIFS(Raw_Data!$G$2:$G$51,Raw_Data!$D$2:$D$51,A16,Raw_Data!$E$2:$E$51,B16),"")
... A24: Account | B24: Critical | C24: =COUNTIFS(Raw_Data!$D$2:$D$51,A24,Raw_Data!$E$2:$E$51,B24) -> 0 | D24: =IFERROR(AVERAGEIFS(Raw_Data!$F$2:$F$51,Raw_Data!$D$2:$D$51,A24,Raw_Data!$E$2:$E$51,B24),"") | E24: =IFERROR(AVERAGEIFS(Raw_Data!$G$2:$G$51,Raw_Data!$D$2:$D$51,A24,Raw_Data!$E$2:$E$51,B24),"")
A25: TOTAL | C25: =SUM(C5:C24) -> 50 | D25: =AVERAGE(Raw_Data!$F$2:$F$51) -> 55.5 | E25: =AVERAGE(Raw_Data!$G$2:$G$51) -> 6.532

Sheet Charts
A1: REQUIRED CHARTS
